{
 "cells": [
  {
   "cell_type": "code",
   "execution_count": 5,
   "metadata": {},
   "outputs": [],
   "source": [
    "import pandas as pd\n",
    "import numpy as np"
   ]
  },
  {
   "cell_type": "code",
   "execution_count": 3,
   "metadata": {},
   "outputs": [
    {
     "name": "stderr",
     "output_type": "stream",
     "text": [
      "/opt/anaconda3/lib/python3.8/site-packages/IPython/core/interactiveshell.py:3165: DtypeWarning: Columns (6,9) have mixed types.Specify dtype option on import or set low_memory=False.\n",
      "  has_raised = await self.run_ast_nodes(code_ast.body, cell_name,\n"
     ]
    }
   ],
   "source": [
    "df = pd.read_csv('~/Desktop/school/info/490/dblp_with_gender.csv')\n"
   ]
  },
  {
   "cell_type": "code",
   "execution_count": 8,
   "metadata": {},
   "outputs": [],
   "source": [
    "chunk = int(np.floor(len(df)/12))"
   ]
  },
  {
   "attachments": {},
   "cell_type": "markdown",
   "metadata": {},
   "source": [
    "Loads the single file, splits it evenly, and downloads it so we can upload to github. Will need the file path and probably the indexes updated depending on who uses it/what changes have been made."
   ]
  },
  {
   "cell_type": "code",
   "execution_count": 10,
   "metadata": {},
   "outputs": [
    {
     "name": "stderr",
     "output_type": "stream",
     "text": [
      "ERROR:root:Internal Python error in the inspect module.\n",
      "Below is the traceback from this internal error.\n",
      "\n",
      "ERROR:root:Internal Python error in the inspect module.\n",
      "Below is the traceback from this internal error.\n",
      "\n",
      "ERROR:root:Internal Python error in the inspect module.\n",
      "Below is the traceback from this internal error.\n",
      "\n"
     ]
    },
    {
     "name": "stdout",
     "output_type": "stream",
     "text": [
      "Traceback (most recent call last):\n",
      "  File \"/opt/anaconda3/lib/python3.8/site-packages/IPython/core/interactiveshell.py\", line 3437, in run_code\n",
      "    exec(code_obj, self.user_global_ns, self.user_ns)\n",
      "  File \"<ipython-input-10-4f1e9115b368>\", line 16, in <module>\n",
      "    df1.to_csv('dblp_with_gender1.csv', encoding='utf-8', index=False)\n",
      "  File \"/opt/anaconda3/lib/python3.8/site-packages/pandas/core/generic.py\", line 3387, in to_csv\n",
      "    return DataFrameRenderer(formatter).to_csv(\n",
      "  File \"/opt/anaconda3/lib/python3.8/site-packages/pandas/io/formats/format.py\", line 1083, in to_csv\n",
      "    csv_formatter.save()\n",
      "  File \"/opt/anaconda3/lib/python3.8/site-packages/pandas/io/formats/csvs.py\", line 228, in save\n",
      "    with get_handle(\n",
      "  File \"/opt/anaconda3/lib/python3.8/site-packages/pandas/io/common.py\", line 642, in get_handle\n",
      "    handle = open(\n",
      "PermissionError: [Errno 1] Operation not permitted: 'dblp_with_gender1.csv'\n",
      "\n",
      "During handling of the above exception, another exception occurred:\n",
      "\n",
      "Traceback (most recent call last):\n",
      "  File \"/opt/anaconda3/lib/python3.8/site-packages/IPython/core/interactiveshell.py\", line 2061, in showtraceback\n",
      "    stb = value._render_traceback_()\n",
      "AttributeError: 'PermissionError' object has no attribute '_render_traceback_'\n",
      "\n",
      "During handling of the above exception, another exception occurred:\n",
      "\n",
      "Traceback (most recent call last):\n",
      "  File \"/opt/anaconda3/lib/python3.8/site-packages/IPython/core/ultratb.py\", line 1101, in get_records\n",
      "    return _fixed_getinnerframes(etb, number_of_lines_of_context, tb_offset)\n",
      "  File \"/opt/anaconda3/lib/python3.8/site-packages/IPython/core/ultratb.py\", line 248, in wrapped\n",
      "    return f(*args, **kwargs)\n",
      "  File \"/opt/anaconda3/lib/python3.8/site-packages/IPython/core/ultratb.py\", line 281, in _fixed_getinnerframes\n",
      "    records = fix_frame_records_filenames(inspect.getinnerframes(etb, context))\n",
      "  File \"/opt/anaconda3/lib/python3.8/inspect.py\", line 1515, in getinnerframes\n",
      "    frameinfo = (tb.tb_frame,) + getframeinfo(tb, context)\n",
      "  File \"/opt/anaconda3/lib/python3.8/inspect.py\", line 1473, in getframeinfo\n",
      "    filename = getsourcefile(frame) or getfile(frame)\n",
      "  File \"/opt/anaconda3/lib/python3.8/inspect.py\", line 708, in getsourcefile\n",
      "    if getattr(getmodule(object, filename), '__loader__', None) is not None:\n",
      "  File \"/opt/anaconda3/lib/python3.8/inspect.py\", line 737, in getmodule\n",
      "    file = getabsfile(object, _filename)\n",
      "  File \"/opt/anaconda3/lib/python3.8/inspect.py\", line 721, in getabsfile\n",
      "    return os.path.normcase(os.path.abspath(_filename))\n",
      "  File \"/opt/anaconda3/lib/python3.8/posixpath.py\", line 379, in abspath\n",
      "    cwd = os.getcwd()\n",
      "PermissionError: [Errno 1] Operation not permitted\n",
      "Traceback (most recent call last):\n",
      "  File \"/opt/anaconda3/lib/python3.8/site-packages/IPython/core/interactiveshell.py\", line 3437, in run_code\n",
      "    exec(code_obj, self.user_global_ns, self.user_ns)\n",
      "  File \"<ipython-input-10-4f1e9115b368>\", line 16, in <module>\n",
      "    df1.to_csv('dblp_with_gender1.csv', encoding='utf-8', index=False)\n",
      "  File \"/opt/anaconda3/lib/python3.8/site-packages/pandas/core/generic.py\", line 3387, in to_csv\n",
      "    return DataFrameRenderer(formatter).to_csv(\n",
      "  File \"/opt/anaconda3/lib/python3.8/site-packages/pandas/io/formats/format.py\", line 1083, in to_csv\n",
      "    csv_formatter.save()\n",
      "  File \"/opt/anaconda3/lib/python3.8/site-packages/pandas/io/formats/csvs.py\", line 228, in save\n",
      "    with get_handle(\n",
      "  File \"/opt/anaconda3/lib/python3.8/site-packages/pandas/io/common.py\", line 642, in get_handle\n",
      "    handle = open(\n",
      "PermissionError: [Errno 1] Operation not permitted: 'dblp_with_gender1.csv'\n",
      "\n",
      "During handling of the above exception, another exception occurred:\n",
      "\n",
      "Traceback (most recent call last):\n",
      "  File \"/opt/anaconda3/lib/python3.8/site-packages/IPython/core/interactiveshell.py\", line 2061, in showtraceback\n",
      "    stb = value._render_traceback_()\n",
      "AttributeError: 'PermissionError' object has no attribute '_render_traceback_'\n",
      "\n",
      "During handling of the above exception, another exception occurred:\n",
      "\n",
      "Traceback (most recent call last):\n",
      "  File \"/opt/anaconda3/lib/python3.8/site-packages/IPython/core/interactiveshell.py\", line 3357, in run_ast_nodes\n",
      "    if (await self.run_code(code, result,  async_=asy)):\n",
      "  File \"/opt/anaconda3/lib/python3.8/site-packages/IPython/core/interactiveshell.py\", line 3454, in run_code\n",
      "    self.showtraceback(running_compiled_code=True)\n",
      "  File \"/opt/anaconda3/lib/python3.8/site-packages/IPython/core/interactiveshell.py\", line 2063, in showtraceback\n",
      "    stb = self.InteractiveTB.structured_traceback(etype,\n",
      "  File \"/opt/anaconda3/lib/python3.8/site-packages/IPython/core/ultratb.py\", line 1367, in structured_traceback\n",
      "    return FormattedTB.structured_traceback(\n",
      "  File \"/opt/anaconda3/lib/python3.8/site-packages/IPython/core/ultratb.py\", line 1267, in structured_traceback\n",
      "    return VerboseTB.structured_traceback(\n",
      "  File \"/opt/anaconda3/lib/python3.8/site-packages/IPython/core/ultratb.py\", line 1124, in structured_traceback\n",
      "    formatted_exception = self.format_exception_as_a_whole(etype, evalue, etb, number_of_lines_of_context,\n",
      "  File \"/opt/anaconda3/lib/python3.8/site-packages/IPython/core/ultratb.py\", line 1082, in format_exception_as_a_whole\n",
      "    last_unique, recursion_repeat = find_recursion(orig_etype, evalue, records)\n",
      "  File \"/opt/anaconda3/lib/python3.8/site-packages/IPython/core/ultratb.py\", line 382, in find_recursion\n",
      "    return len(records), 0\n",
      "TypeError: object of type 'NoneType' has no len()\n",
      "\n",
      "During handling of the above exception, another exception occurred:\n",
      "\n",
      "Traceback (most recent call last):\n",
      "  File \"/opt/anaconda3/lib/python3.8/site-packages/IPython/core/interactiveshell.py\", line 2061, in showtraceback\n",
      "    stb = value._render_traceback_()\n",
      "AttributeError: 'TypeError' object has no attribute '_render_traceback_'\n",
      "\n",
      "During handling of the above exception, another exception occurred:\n",
      "\n",
      "Traceback (most recent call last):\n",
      "  File \"/opt/anaconda3/lib/python3.8/site-packages/IPython/core/ultratb.py\", line 1101, in get_records\n",
      "    return _fixed_getinnerframes(etb, number_of_lines_of_context, tb_offset)\n",
      "  File \"/opt/anaconda3/lib/python3.8/site-packages/IPython/core/ultratb.py\", line 248, in wrapped\n",
      "    return f(*args, **kwargs)\n",
      "  File \"/opt/anaconda3/lib/python3.8/site-packages/IPython/core/ultratb.py\", line 281, in _fixed_getinnerframes\n",
      "    records = fix_frame_records_filenames(inspect.getinnerframes(etb, context))\n",
      "  File \"/opt/anaconda3/lib/python3.8/inspect.py\", line 1515, in getinnerframes\n",
      "    frameinfo = (tb.tb_frame,) + getframeinfo(tb, context)\n",
      "  File \"/opt/anaconda3/lib/python3.8/inspect.py\", line 1473, in getframeinfo\n",
      "    filename = getsourcefile(frame) or getfile(frame)\n",
      "  File \"/opt/anaconda3/lib/python3.8/inspect.py\", line 708, in getsourcefile\n",
      "    if getattr(getmodule(object, filename), '__loader__', None) is not None:\n",
      "  File \"/opt/anaconda3/lib/python3.8/inspect.py\", line 737, in getmodule\n",
      "    file = getabsfile(object, _filename)\n",
      "  File \"/opt/anaconda3/lib/python3.8/inspect.py\", line 721, in getabsfile\n",
      "    return os.path.normcase(os.path.abspath(_filename))\n",
      "  File \"/opt/anaconda3/lib/python3.8/posixpath.py\", line 379, in abspath\n",
      "    cwd = os.getcwd()\n",
      "PermissionError: [Errno 1] Operation not permitted\n",
      "Traceback (most recent call last):\n",
      "  File \"/opt/anaconda3/lib/python3.8/site-packages/IPython/core/interactiveshell.py\", line 3437, in run_code\n",
      "    exec(code_obj, self.user_global_ns, self.user_ns)\n",
      "  File \"<ipython-input-10-4f1e9115b368>\", line 16, in <module>\n",
      "    df1.to_csv('dblp_with_gender1.csv', encoding='utf-8', index=False)\n",
      "  File \"/opt/anaconda3/lib/python3.8/site-packages/pandas/core/generic.py\", line 3387, in to_csv\n",
      "    return DataFrameRenderer(formatter).to_csv(\n",
      "  File \"/opt/anaconda3/lib/python3.8/site-packages/pandas/io/formats/format.py\", line 1083, in to_csv\n",
      "    csv_formatter.save()\n",
      "  File \"/opt/anaconda3/lib/python3.8/site-packages/pandas/io/formats/csvs.py\", line 228, in save\n",
      "    with get_handle(\n",
      "  File \"/opt/anaconda3/lib/python3.8/site-packages/pandas/io/common.py\", line 642, in get_handle\n",
      "    handle = open(\n",
      "PermissionError: [Errno 1] Operation not permitted: 'dblp_with_gender1.csv'\n",
      "\n",
      "During handling of the above exception, another exception occurred:\n",
      "\n",
      "Traceback (most recent call last):\n",
      "  File \"/opt/anaconda3/lib/python3.8/site-packages/IPython/core/interactiveshell.py\", line 2061, in showtraceback\n",
      "    stb = value._render_traceback_()\n",
      "AttributeError: 'PermissionError' object has no attribute '_render_traceback_'\n",
      "\n",
      "During handling of the above exception, another exception occurred:\n",
      "\n",
      "Traceback (most recent call last):\n",
      "  File \"/opt/anaconda3/lib/python3.8/site-packages/IPython/core/interactiveshell.py\", line 3357, in run_ast_nodes\n",
      "    if (await self.run_code(code, result,  async_=asy)):\n",
      "  File \"/opt/anaconda3/lib/python3.8/site-packages/IPython/core/interactiveshell.py\", line 3454, in run_code\n",
      "    self.showtraceback(running_compiled_code=True)\n",
      "  File \"/opt/anaconda3/lib/python3.8/site-packages/IPython/core/interactiveshell.py\", line 2063, in showtraceback\n",
      "    stb = self.InteractiveTB.structured_traceback(etype,\n",
      "  File \"/opt/anaconda3/lib/python3.8/site-packages/IPython/core/ultratb.py\", line 1367, in structured_traceback\n",
      "    return FormattedTB.structured_traceback(\n",
      "  File \"/opt/anaconda3/lib/python3.8/site-packages/IPython/core/ultratb.py\", line 1267, in structured_traceback\n",
      "    return VerboseTB.structured_traceback(\n",
      "  File \"/opt/anaconda3/lib/python3.8/site-packages/IPython/core/ultratb.py\", line 1124, in structured_traceback\n",
      "    formatted_exception = self.format_exception_as_a_whole(etype, evalue, etb, number_of_lines_of_context,\n",
      "  File \"/opt/anaconda3/lib/python3.8/site-packages/IPython/core/ultratb.py\", line 1082, in format_exception_as_a_whole\n",
      "    last_unique, recursion_repeat = find_recursion(orig_etype, evalue, records)\n",
      "  File \"/opt/anaconda3/lib/python3.8/site-packages/IPython/core/ultratb.py\", line 382, in find_recursion\n",
      "    return len(records), 0\n",
      "TypeError: object of type 'NoneType' has no len()\n",
      "\n",
      "During handling of the above exception, another exception occurred:\n",
      "\n",
      "Traceback (most recent call last):\n",
      "  File \"/opt/anaconda3/lib/python3.8/site-packages/IPython/core/interactiveshell.py\", line 2061, in showtraceback\n",
      "    stb = value._render_traceback_()\n",
      "AttributeError: 'TypeError' object has no attribute '_render_traceback_'\n",
      "\n",
      "During handling of the above exception, another exception occurred:\n",
      "\n",
      "Traceback (most recent call last):\n",
      "  File \"/opt/anaconda3/lib/python3.8/site-packages/IPython/core/interactiveshell.py\", line 2940, in _run_cell\n",
      "    return runner(coro)\n",
      "  File \"/opt/anaconda3/lib/python3.8/site-packages/IPython/core/async_helpers.py\", line 68, in _pseudo_sync_runner\n",
      "    coro.send(None)\n",
      "  File \"/opt/anaconda3/lib/python3.8/site-packages/IPython/core/interactiveshell.py\", line 3165, in run_cell_async\n",
      "    has_raised = await self.run_ast_nodes(code_ast.body, cell_name,\n",
      "  File \"/opt/anaconda3/lib/python3.8/site-packages/IPython/core/interactiveshell.py\", line 3376, in run_ast_nodes\n",
      "    self.showtraceback()\n",
      "  File \"/opt/anaconda3/lib/python3.8/site-packages/IPython/core/interactiveshell.py\", line 2063, in showtraceback\n",
      "    stb = self.InteractiveTB.structured_traceback(etype,\n",
      "  File \"/opt/anaconda3/lib/python3.8/site-packages/IPython/core/ultratb.py\", line 1367, in structured_traceback\n",
      "    return FormattedTB.structured_traceback(\n",
      "  File \"/opt/anaconda3/lib/python3.8/site-packages/IPython/core/ultratb.py\", line 1267, in structured_traceback\n",
      "    return VerboseTB.structured_traceback(\n",
      "  File \"/opt/anaconda3/lib/python3.8/site-packages/IPython/core/ultratb.py\", line 1142, in structured_traceback\n",
      "    formatted_exceptions += self.format_exception_as_a_whole(etype, evalue, etb, lines_of_context,\n",
      "  File \"/opt/anaconda3/lib/python3.8/site-packages/IPython/core/ultratb.py\", line 1082, in format_exception_as_a_whole\n",
      "    last_unique, recursion_repeat = find_recursion(orig_etype, evalue, records)\n",
      "  File \"/opt/anaconda3/lib/python3.8/site-packages/IPython/core/ultratb.py\", line 382, in find_recursion\n",
      "    return len(records), 0\n",
      "TypeError: object of type 'NoneType' has no len()\n",
      "\n",
      "During handling of the above exception, another exception occurred:\n",
      "\n",
      "Traceback (most recent call last):\n",
      "  File \"/opt/anaconda3/lib/python3.8/site-packages/IPython/core/interactiveshell.py\", line 2061, in showtraceback\n",
      "    stb = value._render_traceback_()\n",
      "AttributeError: 'TypeError' object has no attribute '_render_traceback_'\n",
      "\n",
      "During handling of the above exception, another exception occurred:\n",
      "\n",
      "Traceback (most recent call last):\n",
      "  File \"/opt/anaconda3/lib/python3.8/site-packages/IPython/core/ultratb.py\", line 1101, in get_records\n",
      "    return _fixed_getinnerframes(etb, number_of_lines_of_context, tb_offset)\n",
      "  File \"/opt/anaconda3/lib/python3.8/site-packages/IPython/core/ultratb.py\", line 248, in wrapped\n",
      "    return f(*args, **kwargs)\n",
      "  File \"/opt/anaconda3/lib/python3.8/site-packages/IPython/core/ultratb.py\", line 281, in _fixed_getinnerframes\n",
      "    records = fix_frame_records_filenames(inspect.getinnerframes(etb, context))\n",
      "  File \"/opt/anaconda3/lib/python3.8/inspect.py\", line 1515, in getinnerframes\n",
      "    frameinfo = (tb.tb_frame,) + getframeinfo(tb, context)\n",
      "  File \"/opt/anaconda3/lib/python3.8/inspect.py\", line 1473, in getframeinfo\n",
      "    filename = getsourcefile(frame) or getfile(frame)\n",
      "  File \"/opt/anaconda3/lib/python3.8/inspect.py\", line 708, in getsourcefile\n",
      "    if getattr(getmodule(object, filename), '__loader__', None) is not None:\n",
      "  File \"/opt/anaconda3/lib/python3.8/inspect.py\", line 737, in getmodule\n",
      "    file = getabsfile(object, _filename)\n",
      "  File \"/opt/anaconda3/lib/python3.8/inspect.py\", line 721, in getabsfile\n",
      "    return os.path.normcase(os.path.abspath(_filename))\n",
      "  File \"/opt/anaconda3/lib/python3.8/posixpath.py\", line 379, in abspath\n",
      "    cwd = os.getcwd()\n",
      "PermissionError: [Errno 1] Operation not permitted\n"
     ]
    }
   ],
   "source": [
    "df = pd.read_csv('~/Desktop/school/info/490/dblp_with_gender.csv')\n",
    "\n",
    "df1 = df.iloc[0:chunk]\n",
    "df2 = df.iloc[chunk+1:2*chunk]\n",
    "df3 = df.iloc[2*chunk+1:3*chunk]\n",
    "df4 = df.iloc[3*chunk+1:4*chunk]\n",
    "df5 = df.iloc[4*chunk+1:5*chunk]\n",
    "df6 = df.iloc[5*chunk+1:6*chunk]\n",
    "df7 = df.iloc[6*chunk+1:7*chunk]\n",
    "df8 = df.iloc[7*chunk+1:8*chunk]\n",
    "df9 = df.iloc[8*chunk+1:9*chunk]\n",
    "df10 = df.iloc[9*chunk+1:10*chunk]\n",
    "df11 = df.iloc[10*chunk+1:11*chunk]\n",
    "df12 = df.iloc[11*chunk+1:len(df)]\n",
    "\n",
    "df1.to_csv('dblp_with_gender1.csv', encoding='utf-8', index=False)\n",
    "df2.to_csv('dblp_with_gender2.csv', encoding='utf-8', index=False)\n",
    "df3.to_csv('dblp_with_gender3.csv', encoding='utf-8', index=False)\n",
    "df4.to_csv('dblp_with_gender4.csv', encoding='utf-8', index=False)\n",
    "df5.to_csv('dblp_with_gender5.csv', encoding='utf-8', index=False)\n",
    "df6.to_csv('dblp_with_gender6.csv', encoding='utf-8', index=False)\n",
    "df7.to_csv('dblp_with_gender7.csv', encoding='utf-8', index=False)\n",
    "df8.to_csv('dblp_with_gender8.csv', encoding='utf-8', index=False)\n",
    "df9.to_csv('dblp_with_gender9.csv', encoding='utf-8', index=False)\n",
    "df10.to_csv('dblp_with_gender10.csv', encoding='utf-8', index=False)\n",
    "df11.to_csv('dblp_with_gender11.csv', encoding='utf-8', index=False)\n",
    "df12.to_csv('dblp_with_gender12.csv', encoding='utf-8', index=False)"
   ]
  },
  {
   "attachments": {},
   "cell_type": "markdown",
   "metadata": {},
   "source": [
    "Combines the multiple files into a single one that is easier to use."
   ]
  },
  {
   "cell_type": "code",
   "execution_count": null,
   "metadata": {},
   "outputs": [],
   "source": [
    "df1 = pd.read_csv('~/Desktop/school/info/490/dblp_with_gender1.csv')\n",
    "df2 = pd.read_csv('~/Desktop/school/info/490/dblp_with_gender2.csv')\n",
    "df3 = pd.read_csv('~/Desktop/school/info/490/dblp_with_gender3.csv')\n",
    "df4 = pd.read_csv('~/Desktop/school/info/490/dblp_with_gender4.csv')\n",
    "df5 = pd.read_csv('~/Desktop/school/info/490/dblp_with_gender5.csv')\n",
    "df6 = pd.read_csv('~/Desktop/school/info/490/dblp_with_gender6.csv')\n",
    "\n",
    "df1 = df1.append(df2, ignore_index = True)\n",
    "df1 = df1.append(df3, ignore_index = True)\n",
    "df1 = df1.append(df4, ignore_index = True)\n",
    "df1 = df1.append(df5, ignore_index = True)\n",
    "df1 = df1.append(df6, ignore_index = True)\n",
    "\n",
    "df = df1\n",
    "\n",
    "df.to_csv('dblp_with_gender.csv', encoding='utf-8', index=False)"
   ]
  }
 ],
 "metadata": {
  "kernelspec": {
   "display_name": "base",
   "language": "python",
   "name": "python3"
  },
  "language_info": {
   "codemirror_mode": {
    "name": "ipython",
    "version": 3
   },
   "file_extension": ".py",
   "mimetype": "text/x-python",
   "name": "python",
   "nbconvert_exporter": "python",
   "pygments_lexer": "ipython3",
   "version": "3.8.8"
  },
  "orig_nbformat": 4,
  "vscode": {
   "interpreter": {
    "hash": "40d3a090f54c6569ab1632332b64b2c03c39dcf918b08424e98f38b5ae0af88f"
   }
  }
 },
 "nbformat": 4,
 "nbformat_minor": 2
}
